Workbook

Sheet Nodes
A1: YW name | B1: Exists in YW? | C1: Monolithic name | D1: Exists in Monolithc? | E1: Modular name | F1: Exists in Modular? | G1: AI Modular v1 name | H1: Exists in Modular? | I1: AI Modular v2 name | J1: Exists in Modular? | K1: Type
A2: /* FUNCTIONS – Nodes representing atomic programs in workflow */ | B2: =COUNTIF(B3:B13,"YES") -> 11 | D2: =COUNTIF(D3:D13,"YES") -> 0 | F2: =COUNTIF(F3:F13,"YES") -> 11 | H2: =COUNTIF(H3:H13,"YES") -> 11 | J2: =COUNTIF(J3:J13,"YES") -> 11 | N2: TP | O2: FN | P2: FP
A3: ReadArgs | B3: YES | D3: NO | E3: read_args | F3: YES | G3: initialize_environment | H3: YES | I3: read_args | J3: YES | K3: FUNCTION | M3: YW | N3: 9.44 | O3: 4.56 | P3: 1.16 | Q3: Modular AI v2
A4: ReadDataFileInput | B4: YES | D4: NO | E4: read_data_file_input | F4: YES | G4: read_data_file_input | H4: YES | I4: read_data_file_input | J4: YES | K4: FUNCTION
A5: CalculateWaveLength | B5: YES | D5: NO | E5: calculate_wavelength | F5: YES | G5: calculate_wavelength | H5: YES | I5: calculate_wavelength | J5: YES | K5: FUNCTION
A6: CalculateIncidentWavePolarization | B6: YES | D6: NO | E6: calculate_incident_wave_polarization | F6: YES | G6: calculate_incident_wave_polarization | H6: YES | I6: calculate_incident_wave_polarization | J6: YES | K6: FUNCTION
A7: ReadModelCoordinates | B7: YES | D7: NO | E7: read_model_coordinates | F7: YES | G7: read_model_coordinates | H7: YES | I7: read_model_coordinates | J7: YES | K7: FUNCTION
A8: ReadFacetsModel | B8: YES | D8: NO | E8: read_facets_model | F8: YES | G8: read_facets_model | H8: YES | I8: read_facets_model | J8: YES | K8: FUNCTION
A9: GenerateTransposeMatrix | B9: YES | D9: NO | E9: generate_transpose_matrix | F9: YES | G9: generate_transpose_matrix | H9: YES | I9: generate_transpose_matrix | J9: YES | K9: FUNCTION
A10: GenerateCoordinatesPoints | B10: YES | D10: NO | E10: generate_coordinates_points | F10: YES | G10: generate_coordinates_points | H10: YES | I10: generate_coordinates_points | J10: YES | K10: FUNCTION
A11: PlotModel | B11: YES | D11: NO | E11: plot_model | F11: YES | G11: plot_model | H11: YES | I11: plot_model | J11: YES | K11: FUNCTION
A12: CalculateRefsGeometryModel | B12: YES | D12: NO | E12: calculate_refs_geometry_model | F12: YES | G12: calculate_refs_geometry_model | H12: YES | I12: calculate_refs_geometry_model | J12: YES | K12: FUNCTION
A13: PrepareOutput | B13: YES | D13: NO | E13: prepare_output | F13: YES | G13: prepare_output | H13: YES | I13: prepare_output | J13: YES | K13: FUNCTION
A15: /* 2nd LEVEL FUNCTIONS – Nodes representing composite programs (sub-workflows) in workflow */ | B15: =COUNTIF(B16:B19,"YES") -> 3 | D15: =COUNTIF(D16:D19,"YES") -> 0 | F15: =COUNTIF(F16:F19,"YES") -> 3 | H15: =COUNTIF(H16:H19,"YES") -> 3 | J15: =COUNTIF(J16:J19,"YES") -> 3
A16: CalculateGlobalAnglesAndDirections | B16: YES | D16: NO | E16: calculate_global_angles_and_directions | F16: YES | G16: calculate_global_angles_and_directions | H16: YES | I16: calculate_global_angles_and_directions | J16: YES | K16: FUNCTION
A17: CalculateSphericalCoordinateSystemRadialUnitVector | B17: YES | D17: NO | E17: calculate_spherical_coordinate_system_radial_unit_vector | F17: YES | G17: calculate_spherical_coordinate_system_radial_unit_vector | H17: YES | I17: calculate_spherical_coordinate_system_radial_unit_vector | J17: YES | K17: FUNCTION
A18: CalculateIncidentFieldInGlobalCartesianCoordinates | B18: YES | D18: NO | E18: calculate_incident_field_in_global_cartesian_coordinates | F18: YES | G18: calculate_incident_field_in_global_cartesian_coordinates | H18: YES | I18: calculate_incident_field_in_global_cartesian_coordinates | J18: YES | K18: FUNCTION
A20: /* VARS, INPUTS, OUTPUTS, PORTS – Nodes for non-parameter data channels in workflow */ | B20: =COUNTIF(B21:B60,"YES") -> 40 | D20: =COUNTIF(D21:D60,"YES") -> 40 | F20: =COUNTIF(F21:F60,"YES") -> 40 | H20: =COUNTIF(H21:H60,"YES") -> 29 | J20: =COUNTIF(J21:J60,"YES") -> 33 | N20: 33 | O20: 7 | P20: 3
A21: Arguments | B21: YES | C21: argv | D21: YES | E21: argv | F21: YES | H21: NO | J21: NO | K21: INPUT | N21: =N3+N20 -> 42.44 | O21: =O3+O20 -> 11.56 | P21: =P3+P20 -> 4.16
A22: CoordinatesFile | B22: YES | C22: BOX/coordinates.m | D22: YES | E22: BOX/coordinates.m | F22: YES | G22: BOX/coordinates.m | H22: YES | I22: BOX/coordinates.m | J22: YES | K22: INPUT
A23: InputDataFile | B23: YES | C23: input_data_file_002.dat | D23: YES | E23: input_data_file_002.dat | F23: YES | G23: input_data_file_002.dat | H23: YES | I23: input_data_file_002.dat | J23: YES | K23: INPUT
A24: FacetsFile | B24: YES | C24: BOX/facets.m | D24: YES | E24: BOX/facets.m | F24: YES | G24: BOX/facets.m | H24: YES | I24: BOX/facets.m | J24: YES | K24: INPUT
A25: R_Output | B25: YES | C25: output/.../R.dat | D25: YES | E25: output/.../R.dat | F25: YES | G25: output/.../R.dat | H25: YES | I25: output/.../R.dat | J25: YES | K25: OUTPUT
A26: E0_Output | B26: YES | C26: output/.../E0.dat | D26: YES | E26: output/.../E0.dat | F26: YES | G26: output/.../E0.dat | H26: YES | I26: output/.../E0.dat | J26: YES | K26: OUTPUT
A27: PlotOutput | B27: YES | C27: output/.../plot.png | D27: YES | E27: output/.../plot.png | F27: YES | G27: output/.../plot.png | H27: YES | I27: output/.../plot.png | J27: YES | K27: OUTPUT
A28: Time | B28: YES | C28: time | D28: YES | E28: time | F28: YES | G28: time | H28: YES | J28: NO | K28: VAR
A29: ProgramName | B29: YES | C29: program_name | D29: YES | E29: program_name | F29: YES | G29: program_name | H29: YES | I29: program_name | J29: YES | K29: VAR
A30: InputDataFileName | B30: YES | C30: input_data_file | D30: YES | E30: input_data_file | F30: YES | G30: input_data_file | H30: YES | I30: input_data_file | J30: YES | K30: VAR
A31: InputModel | B31: YES | C31: input_model | D31: YES | E31: input_model | F31: YES | G31: input_model | H31: YES | I31: input_model | J31: YES | K31: VAR
A32: OutputDir | B32: YES | C32: output_dir | D32: YES | E32: output_dir | F32: YES | G32: output_dir | H32: YES | I32: output_dir | J32: YES | K32: VAR
A33: Freq | B33: YES | C33: freq | D33: YES | E33: freq | F33: YES | G33: freq | H33: YES | I33: freq | J33: YES | K33: VAR
A34: Corr | B34: YES | C34: corr | D34: YES | E34: corr | F34: YES | G34: corr | H34: YES | I34: corr | J34: YES | K34: VAR
A35: Delstd | B35: YES | C35: delstd | D35: YES | E35: delstd | F35: YES | G35: delstd | H35: YES | I35: delstd | J35: YES | K35: VAR
A36: InputPolarization | B36: YES | C36: ipol | D36: YES | E36: ipol | F36: YES | G36: ipol | H36: YES | I36: ipol | J36: YES | K36: VAR
A37: PStart | B37: YES | C37: pstart | D37: YES | E37: pstart | F37: YES | G37: pstart | H37: YES | I37: pstart | J37: YES | K37: VAR
A38: PStop | B38: YES | C38: pstop | D38: YES | E38: pstop | F38: YES | G38: pstop | H38: YES | I38: pstop | J38: YES | K38: VAR
A39: InputDelP | B39: YES | C39: delp | D39: YES | E39: delp | F39: YES | G39: delp | H39: YES | I39: delp | J39: YES | K39: VAR
A40: TStart | B40: YES | C40: tstart | D40: YES | E40: tstart | F40: YES | G40: tstart | H40: YES | I40: tstart | J40: YES | K40: VAR
... A42: InputDelT | B42: YES | C42: delt | D42: YES | E42: delt | F42: YES | G42: delt | H42: YES | I42: delt | J42: YES | K42: VAR
A43: WaveLength | B43: YES | C43: waveL | D43: YES | E43: waveL | F43: YES | G43: waveL | H43: YES | J43: NO | K43: VAR
...

Sheet Edges
A1: Type | B1: YW From | C1: YW To | D1: Exists in YW | E1: Modular To | F1: Modular From | G1: Exists in Modular | H1: Exists in Monolithic
D2: =COUNTIF(D3:D146,"YES") -> 95 | G2: =COUNTIF(G3:G146,"YES") -> 94 | H2: =COUNTIF(H3:H146,"YES") -> 0
B4: ReadArgs | D4: =COUNTIF(D5:D10,"YES") -> 6 | E4: read_args | G4: =COUNTIF(G5:G10,"YES") -> 6 | H4: =COUNTIF(H5:H10,"YES") -> 0
A5: INPUT | B5: Arguments | C5: ReadArgs | D5: YES | E5: argv | F5: read_args | G5: YES | H5: NO
A6: OUTPUT | B6: ReadArgs | C6: Time | D6: YES | E6: read_args | F6: time | G6: YES | H6: NO
A7: OUTPUT | B7: ReadArgs | C7: ProgramName | D7: YES | E7: read_args | F7: program_name | G7: YES | H7: NO
A8: OUTPUT | B8: ReadArgs | C8: InputDataFileName | D8: YES | E8: read_args | F8: input_data_file | G8: YES | H8: NO
A9: OUTPUT | B9: ReadArgs | C9: InputModel | D9: YES | E9: read_args | F9: input_model | G9: YES | H9: NO
A10: OUTPUT | B10: ReadArgs | C10: OutputDir | D10: YES | E10: read_args | F10: output_dir | G10: YES | H10: NO
B12: ReadDataFileInput | D12: =COUNTIF(D13:D24,"YES") -> 12 | E12: read_data_file_input | G12: =COUNTIF(G13:G24,"YES") -> 12 | H12: =COUNTIF(H13:H24,"YES") -> 0
A13: INPUT | B13: InputDataFileName | C13: ReadDataFileInput | D13: YES | E13: input_data_file | F13: read_data_file_input | G13: YES | H13: NO
A14: INPUT | B14: InputDataFile | C14: ReadDataFileInput | D14: YES | E14: input_data_file_001.dat | F14: read_data_file_input | G14: YES | H14: NO
A15: OUTPUT | B15: ReadDataFileInput | C15: Freq | D15: YES | E15: read_data_file_input | F15: freq | G15: YES | H15: NO
A16: OUTPUT | B16: ReadDataFileInput | C16: Corr | D16: YES | E16: read_data_file_input | F16: corr | G16: YES | H16: NO
A17: OUTPUT | B17: ReadDataFileInput | C17: Delstd | D17: YES | E17: read_data_file_input | F17: delstd | G17: YES | H17: NO
A18: OUTPUT | B18: ReadDataFileInput | C18: InputPolarization | D18: YES | E18: read_data_file_input | F18: ipol | G18: YES | H18: NO
A19: OUTPUT | B19: ReadDataFileInput | C19: PStart | D19: YES | E19: read_data_file_input | F19: pstart | G19: YES | H19: NO
A20: OUTPUT | B20: ReadDataFileInput | C20: PStop | D20: YES | E20: read_data_file_input | F20: pstop | G20: YES | H20: NO
A21: OUTPUT | B21: ReadDataFileInput | C21: InputDelP | D21: YES | E21: read_data_file_input | F21: delp | G21: YES | H21: NO
A22: OUTPUT | B22: ReadDataFileInput | C22: TStart | D22: YES | E22: read_data_file_input | F22: tstart | G22: YES | H22: NO
A23: OUTPUT | B23: ReadDataFileInput | C23: TStop | D23: YES | E23: read_data_file_input | F23: tstop | G23: YES | H23: NO
A24: OUTPUT | B24: ReadDataFileInput | C24: InputDelT | D24: YES | E24: read_data_file_input | F24: delt | G24: YES | H24: NO
B26: CalculateWaveLength | D26: =COUNTIF(D27:D28,"YES") -> 2 | E26: calculate_wavelength | G26: =COUNTIF(G27:G28,"YES") -> 2 | H26: =COUNTIF(H27:H28,"YES") -> 0
A27: INPUT | B27: Freq | C27: CalculateWaveLength | D27: YES | E27: freq | F27: calculate_wavelength | G27: YES | H27: NO
A28: OUTPUT | B28: CalculateWaveLength | C28: WaveLength | D28: YES | E28: calculate_wavelength | F28: waveL | G28: YES | H28: NO
B30: CalculateIncidentWavePolarization | D30: =COUNTIF(D31:D34,"YES") -> 4 | E30: calculate_incident_wave_polarization | G30: =COUNTIF(G31:G34,"YES") -> 4 | H30: =COUNTIF(H31:H34,"YES") -> 0
A31: INPUT | B31: InputPolarization | C31: CalculateIncidentWavePolarization | D31: YES | E31: ipol | F31: calculate_incident_wave_polarization | G31: YES | H31: NO
A32: INPUT | B32: WaveLength | C32: CalculateIncidentWavePolarization | D32: YES | E32: waveL | F32: calculate_incident_wave_polarization | G32: YES | H32: NO
A33: OUTPUT | B33: CalculateIncidentWavePolarization | C33: Et | D33: YES | E33: calculate_incident_wave_polarization | F33: et | G33: YES | H33: NO
A34: OUTPUT | B34: CalculateIncidentWavePolarization | C34: Ep | D34: YES | E34: calculate_incident_wave_polarization | F34: ep | G34: YES | H34: NO
B36: ReadModelCoordinates | D36: =COUNTIF(D37:D42,"YES") -> 6 | E36: read_model_coordinates | G36: =COUNTIF(G37:G42,"YES") -> 6 | H36: =COUNTIF(H37:H42,"YES") -> 0
A37: INPUT | B37: InputModel | C37: ReadModelCoordinates | D37: YES | E37: input_model | F37: read_model_coordinates | G37: YES | H37: NO
A38: INPUT | B38: CoordinatesFile | C38: ReadModelCoordinates | D38: YES | E38: ...coordinates.m | F38: read_model_coordinates | G38: YES | H38: NO
A39: OUTPUT | B39: ReadModelCoordinates | C39: XPoints | D39: YES | E39: read_model_coordinates | F39: xpts | G39: YES | H39: NO
A40: OUTPUT | B40: ReadModelCoordinates | C40: YPoints | D40: YES | E40: read_model_coordinates | F40: ypts | G40: YES | H40: NO
A41: OUTPUT | B41: ReadModelCoordinates | C41: ZPoints | D41: YES | E41: read_model_coordinates | F41: zpts | G41: YES | H41: NO
A42: OUTPUT | B42: ReadModelCoordinates | C42: Nverts | D42: YES | E42: read_model_coordinates | F42: nverts | G42: YES | H42: NO
B44: ReadFacetsModel | D44: =COUNTIF(D45:D47,"YES") -> 3 | E44: read_facets_model | G44: =COUNTIF(G45:G47,"YES") -> 3 | H44: =COUNTIF(H45:H47,"YES") -> 0
A45: INPUT | B45: InputModel | C45: ReadFacetsModel | D45: YES | E45: input_model | F45: read_facets_model | G45: YES | H45: NO
A46: INPUT | B46: FacetsFile | C46: ReadFacetsModel | D46: YES | E46: ...facets.m | F46: read_facets_model | G46: YES | H46: NO
...

Sheet Analysis_2018
A1: Node Types
A2: VAR | B2: =COUNTIF(Nodes!K$3:K$74, "VAR") -> 34
A3: FUNCTION | B3: =COUNTIF(Nodes!K$3:K$74, "FUNCTION") -> 14
A4: INPUT | B4: =COUNTIF(Nodes!K$3:K$74, "INPUT") -> 4
A5: OUTPUT | B5: =COUNTIF(Nodes!K$3:K$74, "OUTPUT") -> 3
A6: 1st LEVEL FUNCTIONS | B6: =Nodes!B2 -> 11
A7: 2nd LEVEL FUNCTIONS | B7: =Nodes!B15 -> 3
A11: Nodes YW-Modular
A13: YW Program Ports | B13: =COUNTIF(Nodes!B$3:B$74, "PORT") -> 7 | D13: (We may add it to YW Only)
A15: YW Only | B15: =COUNTIFS(Nodes!B$3:B$74, "YES", Nodes!F$3:F$74, "NO") -> 0 | C15: FN
A16: Modular Only | B16: =COUNTIFS(Nodes!B$3:B$74, "NO", Nodes!F$3:F$74, "YES") -> 1 | C16: FP
A17: Intersection YW-Modular | B17: =COUNTIFS(Nodes!B$3:B$74, "YES", Nodes!F$3:F$74, "YES") -> 54 | C17: TP
A19: Total YW | B19: =B15+B17 -> 54
A20: Total Modular | B20: =B16+B17 -> 55
A22: Precision | B22: =B17/(B17 + B16) -> 0.98181818 | C22: TP/(TP+FP)
A23: Recall | B23: =B17/(B17+B15+7) -> 0.8852459 | C23: TP/(TP+FN)
A24: F-Measure | B24: =2/((1/B23)+(1/B22)) -> 0.93103448
A27: Edges YW-Modular
A29: YW Program Ports | B29: =COUNTIF(Edges!D5:D139, "PORT") -> 7 | D29: (We may add it to YW Only)
A31: YW Only | B31: =COUNTIFS(Edges!D5:D139, "YES", Edges!G5:G139, "NO") -> 4 | C31: FN
A32: Modular Only | B32: =COUNTIFS(Edges!D6:D140, "NO", Edges!G6:G140, "YES") -> 3 | C32: FP
A33: Intersection YW-Modular | B33: =COUNTIFS(Edges!D7:D141, "YES", Edges!G7:G141, "YES") -> 89 | C33: TP
A35: Total YW | B35: =B31+B33 -> 93
A36: Total Modular | B36: =B32+B33 -> 92
A38: Precision | B38: =B33/(B33 + B32) -> 0.9673913 | C38: TP/(TP+FP)
A39: Recall | B39: =B33/(B33+B31) -> 0.95698925 | C39: TP/(TP+FN)
A43: Nodes YW-Monolithic
A45: YW Program Ports | B45: =COUNTIF(Nodes!B$3:B$74, "PORT") -> 7 | D45: (We may add it to YW Only)
A46: gc -n monolithic.dot | B46: 720
A48: YW Only | B48: =COUNTIFS(Nodes!B$3:B$74, "YES", Nodes!D$3:D$74, "NO") -> 14 | C48: FN
A49: Monolithic Only | B49: =B46-B50 -> 680 | C49: FP
A50: Intersection YW-Monolithic | B50: =COUNTIFS(Nodes!B$3:B$74, "YES", Nodes!D$3:D$74, "YES") -> 40 | C50: TP
A52: Total YW | B52: =B48+B50 -> 54
A53: Total Modular | B53: =B49+B50 -> 720
A55: Precision | B55: =B50/(B50 + B49) -> 0.055555556 | C55: TP/(TP+FP)
A56: Recall | B56: =B50/(B50+B48+7) -> 0.6557377 | C56: TP/(TP+FN)
A57: F-Measure | B57: =2/((1/B56)+(1/B55)) -> 0.10243278
A60: Egdes YW-Monolithic
A62: YW Program Ports | B62: =COUNTIF(Edges!D5:D139, "PORT") -> 7
A63: gc -e monolithic.dot | B63: 1388
...

Sheet Analysis
A1: Analysis: values reported in the revised paper (2026). Computed by the scripts in analysis/ on the graphs in output/provenance; the complete outputs (trails, matched nodes and edges) are in analysis/results/. The sheet Analysis_2018 keeps the original computation over the graphs of the first submission and is superseded.
A3: Table 3 (Section 4.6.2): functional and variable components
A4: Version | B4: |AI| | C4: TP_func AI->G | D4: FP_func | E4: TP_func G->AI | F4: FN_func | G4: |G| | H4: TP_var | I4: FP_var | J4: FN_var (incl. 7 ports) | K4: SP | L4: SR | M4: SF
A5: Monolithic | B5: 0 | C5: 0 | D5: 0 | E5: 0 | F5: 14 | G5: 14 | H5: 16 | I5: 861 | J5: 31 | K5: 0.018 | L5: 0.262 | M5: 0.034
A6: Expert-modularized | B6: 14 | C6: 14 | D6: 0 | E6: 14 | F6: 0 | G6: 14 | H6: 40 | I6: 1 | J6: 7 | K6: 0.982 | L6: 0.885 | M6: 0.931
A7: LLM-modularized (Gemini) | B7: 8 | C7: 6.83 | D7: 1.17 | E7: 9.43 | F7: 4.57 | G7: 14 | H7: 31 | I7: 6 | J7: 16 | K7: 0.841 | L7: 0.663 | M7: 0.741
A9: Figure 8 (Section 4.6.1): monolithic graph, exact matching over all nodes
A10: Version | B10: TP | C10: FP | D10: FN | E10: Precision | F10: Recall | G10: F-Measure
A11: Monolithic | B11: 16 | C11: 1343 | D11: 45 | E11: 0.012 | F11: 0.262 | G11: 0.023
A13: Edge comparison (Section 4.6.1): one-to-one, orientation ignored; sheet Edges with row 10 corrected
A14: Version | B14: Ground-truth edges | C14: Candidate graph edges | D14: TP | E14: FN | F14: FP | G14: Precision | H14: Recall | I14: F-Measure
A15: Expert-modularized | B15: 95 | C15: 93 | D15: 89 | E15: 6 | F15: 4 | G15: 0.957 | H15: 0.937 | I15: 0.947
A16: Monolithic | B16: 95 | C16: 63 | D16: 0 | E16: 95 | F16: 63 | G16: 0 | H16: 0 | I16: 0
A18: Robustness check (Section 9): top-level variables matched by name and final value, no ports
A19: Version | B19: TP | C19: FP | D19: FN | E19: SP | F19: SR | G19: SF
A20: Monolithic | B20: 22 | C20: 56 | D20: 15 | E20: 0.282 | F20: 0.431 | G20: 0.341
A21: LLM-modularized (Gemini) | B21: 20 | C21: 14 | D21: 17 | E21: 0.639 | F21: 0.577 | G21: 0.606
A22: Expert-modularized (self-comparison) | B22: 37 | C22: 0 | D22: 0 | E22: 1 | F22: 1 | G22: 1
